<?xml version="1.0" ?>
<robot name="door">
  <link name="world"/>

  <joint name="palm_to_world" type="fixed">
    <parent link="world"/>
    <child link="palm"/>
    <origin xyz="0.5 0.45 0.5" rpy="0 0 0" />
  </joint>

  <link name="palm">
    <inertial>
       <origin rpy="0 0 0" xyz="0 0 0"/>
       <mass value="0.01125"/>
       <inertia ixx="2.83203125E-06" ixy="0" ixz="-3.38813179E-22" iyy="7.83203125E-06" iyz="8.47032947E-23" izz="1.06250000E-05"/>
    </inertial>
    <visual>
      <origin rpy="0 0 0" xyz="0 0 0"/>
      <geometry> <mesh filename="palm.obj" scale="1.0 1.0 1.0"/> </geometry>
      <material name="white"> <color rgba="0.9 0.9 0.95 1"/> </material>
    </visual>
    <collision>
      <origin rpy="0 0 0" xyz="0 0 0"/>
      <geometry> <mesh filename="palm.obj" scale="1.0 1.0 1.0"/> </geometry>
    </collision>
  </link>

  <joint name="finger1_to_palm" type="prismatic">
    <parent link="palm"/>
    <child link="finger1"/>
    <origin xyz="-0.15 -0.25 0.0" rpy="0 0 0" />
    <axis
      xyz="1 0 0" />
    <limit
      lower="-3.0"
      upper="3.0"
      effort="0"
      velocity="10.0" />
  </joint>

  <link name="finger1">
    <inertial>
       <origin rpy="0 0 0" xyz="0 0 0"/>
       <mass value="1.0"/>
       <inertia ixx="1.0" ixy="0" ixz="0" iyy="1.0" iyz="0" izz="1.0"/>
    </inertial>
    <visual>
      <origin rpy="0 0 0" xyz="0 0 0"/>
      <geometry> <mesh filename="finger.obj" scale="1.0 1.0 1.0"/> </geometry>
      <material name="black"> <color rgba="0.2 0.2 0.2 1.0"/> </material>
    </visual>
    <collision>
      <origin rpy="0 0 0" xyz="0 0 0"/>
      <geometry> <mesh filename="finger.obj" scale="1.0 1.0 1.0"/> </geometry>
    </collision>
  </link>
  
  <joint name="finger2_to_palm" type="prismatic">
    <parent link="palm"/>
    <child link="finger2"/>
    <origin xyz="0.15 -0.25 0.0" rpy="0 0 0" />
    <axis
      xyz="1 0 0" />
    <limit
      lower="-3.0"
      upper="3.0"
      effort="0"
      velocity="10.0" />
  </joint>

  <link name="finger2">
    <inertial>
       <origin rpy="0 0 0" xyz="0 0 0"/>
       <mass value="1.0"/>
       <inertia ixx="1.0" ixy="0" ixz="0" iyy="1.0" iyz="0" izz="1.0"/>
    </inertial>
    <visual>
      <origin rpy="0 0 0" xyz="0 0 0"/>
      <geometry> <mesh filename="finger.obj" scale="1.0 1.0 1.0"/> </geometry>
      <material name="black"> <color rgba="0.2 0.2 0.2 1.0"/> </material>
    </visual>
    <collision>
      <origin rpy="0 0 0" xyz="0 0 0"/>
      <geometry> <mesh filename="finger.obj" scale="1.0 1.0 1.0"/> </geometry>
    </collision>
  </link>
</robot>
