<?xml version="1.0" ?>
<robot name="glass">
  <link name="world"/>
  <joint name="glass_to_world" type="floating">
    <parent link="world"/>
    <child link="base_link"/>
    <origin xyz="0 0 0" rpy="0 0 0" />
  </joint>
  <link name="base_link">
    <inertial>
       <origin rpy="0 0 0" xyz="0 0 0"/>
       <mass value="2.2687400131198525"/>
       <inertia ixx="0.03433209139724946" ixy="1.7920980509046207e-06" ixz="-1.0351848081649634e-05" iyx="1.7920980509046207e-06" iyy="0.01000445384192556" iyz="6.2724331211695816e-06" izx="-1.0351848081649634e-05" izy="6.2724331211695816e-06" izz="0.034329769220318086"/>
    </inertial>
    <visual>
      <origin rpy="0 0 0" xyz="0 0 0"/>
      <geometry> <mesh filename="glass.obj" scale="1.0 1.0 1.0"/> </geometry>
      <material name="white"> <color rgba="0.7843137254901961 0.1411764705882353 0.17254901960784313 0.8"/> </material>
    </visual>
    <collision>
      <origin rpy="0 0 0" xyz="0 0 0"/>
      <geometry> <mesh filename="glass.obj" scale="1.0 1.0 1.0"/> </geometry>
    </collision>
  </link>
</robot>
