<?xml version="1.0" ?>
<robot name="door">
  <link name="world"/>

  <joint name="door_to_world" type="revolute">
    <parent link="world"/>
    <child link="base_link"/>
    <origin xyz="0.25 0.0 0.3" rpy="0 0 0" />
    <axis
      xyz="0 1 0" />
    <limit
      lower="-3.14"
      upper="3.14"
      effort="0"
      velocity="6.545" />
  </joint>

  <link name="base_link">
    <inertial>
       <origin rpy="0 0 0" xyz="0 0 0"/>
       <mass value="0.01125"/>
       <inertia ixx="2.83203125E-06" ixy="0" ixz="-3.38813179E-22" iyy="7.83203125E-06" iyz="8.47032947E-23" izz="1.06250000E-05"/>
    </inertial>
    <visual>
      <origin rpy="0 0 0" xyz="0 0 0"/>
      <geometry> <mesh filename="door.obj" scale="1.0 1.0 1.0"/> </geometry>
      <material name="white"> <color rgba="0.7843137254901961 0.1411764705882353 0.17254901960784313 1.0"/> </material>
    </visual>
    <collision>
      <origin rpy="0 0 0" xyz="0 0 0"/>
      <geometry> <mesh filename="door.obj" scale="1.0 1.0 1.0"/> </geometry>
    </collision>
  </link>
</robot>
